Workbook

Sheet 00_Cover
A1: GEO COMPLETE MODEL v2 — FORMULA-DRIVEN
A2: Edit only BLUE cells on 01_Inputs (and blue cells elsewhere). Everything else recalculates.
A4: LIVE OUTPUTS
A5: Price | B5: =01_Inputs!B6
A6: Mkt cap $M | B6: =01_Inputs!B11
A7: Cash $M | B7: =01_Inputs!B16
A8: Net debt $M | B8: =01_Inputs!B18
A9: P/E FY26 guide | B9: =01_Inputs!B78
A10: EV/EBITDA FY26 | B10: =01_Inputs!B79
A11: SOTP A (seg mult) $/sh | B11: =07_SOTP!B8
A12: SOTP B (full ICE) $/sh | B12: =07_SOTP!B19
A13: SOTP C (full RE NAV) $/sh | B13: =07_SOTP!B29
A14: SOTP D (several) $/sh | B14: =07_SOTP!B38
A15: Prob-weighted $/sh | B15: =09_Scenarios!C10
A17: SHEET MAP
A18: 01_Inputs — ALL drivers (beds, prices, tax, growth, margins, multiples)
A19: 02_Hist — historical IS/BS (editable actuals)
A20: 03_Segments — segment P&L FY26–29 + MULTIPLES SECTION at bottom
A21: 04_IS_Fwd — consolidated P&L, EPS, FCF, PE paths
A22: 05_BS_Fwd — cash, debt, leverage (cash included explicitly)
A23: 06_RE_NAV — bed × $/bed × net take; residual EBITDA
A24: 07_SOTP — four approaches, cash/debt treated once
A25: 08_CXW_Comps — trading + transaction comps
A26: 09_Scenarios — probabilities + weighted value + PE compression

Sheet 01_Inputs
A1: GEO — MODEL INPUTS (edit blue cells only)
A2: All other sheets pull from here via formulas. Blue font + blue fill = INPUT.
A4: MARKET
A5: Parameter | B5: Value | C5: Unit | D5: Notes
A6: GEO price | B6: 31.75 | C6: $/sh | D6: Edit to refresh valuation
A7: GEO shares outstanding | B7: 131.62 | C7: M
A8: GEO diluted WAS (FY26 guide) | B8: 132.6 | C8: M
A9: CXW price | B9: 33.92 | C9: $/sh
A10: CXW shares | B10: 98.89 | C10: M
A11: GEO mkt cap | B11: =B6*B7 | C11: $M
A12: CXW mkt cap | B12: =B9*B10 | C12: $M
A14: BALANCE SHEET SNAPSHOT (6/30/26)
A15: Parameter | B15: Value | C15: Unit | D15: Notes
A16: Cash & equiv | B16: 55 | C16: $M | D16: 2Q26 BS — INCLUDE in equity bridge
A17: Gross debt | B17: 1542.3 | C17: $M
A18: Net debt | B18: =B17-B16 | C18: $M
A19: PP&E net | B19: 1856.8 | C19: $M
A20: Book equity | B20: 1514.7 | C20: $M
A21: Accounts receivable | B21: 531.9 | C21: $M
A22: Idle facilities NBV | B22: 152.8 | C22: $M
A23: Enterprise value | B23: =B11+B18 | C23: $M
A25: TAX & SALE FRICTION
A26: Parameter | B26: Value | C26: Unit | D26: Notes
A27: Federal corporate tax rate | B27: 0.21 | D27: Statutory 21%
A28: Blended state + other | B28: 0.05 | D28: CA/TX etc. on gains; editable
A29: Combined statutory (ex discrete) | B29: =B27+B28
A30: Company FY26 ETR (ops guide) | B30: 0.3 | D30: Guide ~30% incl discrete — use for P&L
A31: Transaction costs % of gross | B31: 0.04 | D31: Legal, broker, etc.
A32: Est. tax on RE gain (fed+state) | B32: 0.25 | D32: CXW paid ~$0.5B tax on $2.2B ≈ 23%; book basis low → use 25% base
A33: Net proceeds / gross | B33: =1-B32-B31
D34: CXW observed ~71-73%. Override B32/B31 to match. NOT the same as 21% statutory on full sale price (basis matters).
A36: OWNED BED INVENTORY
A37: Parameter | B37: Value | C37: Unit | D37: Notes
A38: Owned ICE primary beds | B38: 25479
A39: Joe Corley dual beds | B39: 1517
A40: ICE + dual | B40: =B38+B39
A41: Owned USMS beds | B41: 8591
A42: Owned state (Riverbend) | B42: 1500
A43: Owned idle secure | B43: 4576
A44: Other owned secure | B44: =B41+B42+B43
...

Sheet 02_Hist
A1: HISTORICAL FINANCIALS ($M) — blue = editable actuals
A2: Year | B2: 2022A | C2: 2023A | D2: 2024A | E2: 2025A | F2: 1H26A | G2: Source
A3: Revenue | B3: 2376.7 | C3: 2413.2 | D3: 2423.7 | E3: 2631.5 | F3: 1437.3
A4: Adj EBITDA | B4: 533 | C4: 486 | D4: 463.5 | E4: 464.4 | F4: 273.4
A5: GAAP NI | B5: 171.8 | C5: 107.3 | D5: 32 | E5: 254.4 | F5: 85.8
A6: EPS diluted | B6: 1.4 | C6: 0.87 | D6: 0.24 | E6: 1.82 | F6: 0.65
A7: D&A | B7: 132.9 | C7: 125.8 | D7: 126.2 | E7: 132 | F7: 68
A8: Interest exp | B8: 164.6 | C8: 218.3 | D8: 190.6 | E8: 160.5 | F8: 76.9
A9: Cash | B9: 95.1 | C9: 94 | D9: 76.9 | E9: 69 | F9: 55
A10: Gross debt | B10: 2074.3 | C10: 1888.1 | D10: 1811.8 | E10: 1725.4 | F10: 1542.3
A11: Net debt | B11: 1979.2 | C11: 1794.1 | D11: 1734.9 | E11: 1656.4 | F11: 1487.3
A12: PP&E | B12: 2093 | C12: 2046.5 | D12: 1995 | E12: 1956.5 | F12: 1856.8
A13: Equity | B13: 1166.4 | C13: 1291.8 | D13: 1334.9 | E13: 1505.8 | F13: 1514.7
A14: Diluted shares M | B14: 122.3 | C14: 123.7 | D14: 134.1 | E14: 139.7 | F14: 133
A16: Rev YoY % | C16: =C3/B3-1 | D16: =D3/C3-1 | E16: =E3/D3-1
A17: Adj EBITDA margin % | B17: =B4/B3 | C17: =C4/C3 | D17: =D4/D3 | E17: =E4/E3 | F17: =F4/F3
A18: Net leverage (x) | B18: =B11/B4 | C18: =C11/C4 | D18: =D11/D4 | E18: =E11/E4 | F18: =F11/F4

Sheet 03_Segments
A1: SEGMENT MODEL — Q2 build → FY26E–29E (all formulas from 01_Inputs)
A2: Edit growth rates & margins on 01_Inputs rows 88–92 and seeds rows 96–100.
B4: FY26E | C4: FY27E | D4: FY28E | E4: FY29E
A5: Owned Secure Revenue $M | B5: =01_Inputs!E96 | C5: =B5*(1+01_Inputs!B88) | D5: =C5*(1+01_Inputs!C88) | E5: =D5*(1+01_Inputs!D88)
A6: Owned Secure NOI margin | B6: =01_Inputs!E88 | C6: =01_Inputs!F88 | D6: =01_Inputs!G88 | E6: =01_Inputs!H88
A7: Owned Secure NOI $M | B7: =B5*B6 | C7: =C5*C6 | D7: =D5*D6 | E7: =E5*E6
A9: Owned Reentry Revenue $M | B9: =01_Inputs!E97 | C9: =B9*(1+01_Inputs!B89) | D9: =C9*(1+01_Inputs!C89) | E9: =D9*(1+01_Inputs!D89)
A10: Owned Reentry NOI margin | B10: =01_Inputs!E89 | C10: =01_Inputs!F89 | D10: =01_Inputs!G89 | E10: =01_Inputs!H89
A11: Owned Reentry NOI $M | B11: =B9*B10 | C11: =C9*C10 | D11: =D9*D10 | E11: =E9*E10
A13: Managed Only Revenue $M | B13: =01_Inputs!E98 | C13: =B13*(1+01_Inputs!B90) | D13: =C13*(1+01_Inputs!C90) | E13: =D13*(1+01_Inputs!D90)
A14: Managed Only NOI margin | B14: =01_Inputs!E90 | C14: =01_Inputs!F90 | D14: =01_Inputs!G90 | E14: =01_Inputs!H90
A15: Managed Only NOI $M | B15: =B13*B14 | C15: =C13*C14 | D15: =D13*D14 | E15: =E13*E14
A17: EM Revenue $M | B17: =01_Inputs!E99 | C17: =B17*(1+01_Inputs!B91) | D17: =C17*(1+01_Inputs!C91) | E17: =D17*(1+01_Inputs!D91)
A18: EM NOI margin | B18: =01_Inputs!E91 | C18: =01_Inputs!F91 | D18: =01_Inputs!G91 | E18: =01_Inputs!H91
A19: EM NOI $M | B19: =B17*B18 | C19: =C17*C18 | D19: =D17*D18 | E19: =E17*E18
A21: NonRes Revenue $M | B21: =01_Inputs!E100 | C21: =B21*(1+01_Inputs!B92) | D21: =C21*(1+01_Inputs!C92) | E21: =D21*(1+01_Inputs!D92)
A22: NonRes NOI margin | B22: =01_Inputs!E92 | C22: =01_Inputs!F92 | D22: =01_Inputs!G92 | E22: =01_Inputs!H92
A23: NonRes NOI $M | B23: =B21*B22 | C23: =C21*C22 | D23: =D21*D22 | E23: =E21*E22
A25: TOTAL Segment Rev $M | B25: =B5+B9+B13+B17+B21 | C25: =C5+C9+C13+C17+C21 | D25: =D5+D9+D13+D17+D21 | E25: =E5+E9+E13+E17+E21
A26: TOTAL Segment NOI $M | B26: =B7+B11+B15+B19+B23 | C26: =C7+C11+C15+C19+C23 | D26: =D7+D11+D15+D19+D23 | E26: =E7+E11+E15+E19+E23
A28: G&A $M | B28: =01_Inputs!B83 | C28: =B28*(1+01_Inputs!B84) | D28: =C28*(1+01_Inputs!B84) | E28: =D28*(1+01_Inputs!B84)
A29: NOI − G&A (proxy op. profit) | B29: =B26-B28 | C29: =C26-C28 | D29: =D26-D28 | E29: =E26-E28
A30: Adj EBITDA bridge (scale to guide yr1) | B30: =01_Inputs!B71 | C30: =B30*(C29/B29) | D30: =C30*(D29/C29) | E30: =D30*(E29/D29)
A32: SEGMENT MULTIPLES VALUATION (applied to FY26E NOI unless noted)
A33: Uses 01_Inputs!B105:D110 multiples. WARNING: Owned Secure multiple DOUBLE-COUNTS if you also add full RE NAV — pick one approach in 07_SOTP.
A34: Segment | B34: FY26E NOI | C34: Base multiple | D34: EV base | E34: Bull EV | F34: Bear EV | G34: % of Base EV
A35: Owned Secure | B35: =B7 | C35: =01_Inputs!C105 | D35: =B35*C35 | E35: =B35*01_Inputs!B105 | F35: =B35*01_Inputs!D105 | G35: =D35/D$41
A36: Owned Reentry | B36: =B11 | C36: =01_Inputs!C106 | D36: =B36*C36 | E36: =B36*01_Inputs!B106 | F36: =B36*01_Inputs!D106 | G36: =D36/D$41
A37: Managed Only | B37: =B15 | C37: =01_Inputs!C107 | D37: =B37*C37 | E37: =B37*01_Inputs!B107 | F37: =B37*01_Inputs!D107 | G37: =D37/D$41
A38: EM | B38: =B19 | C38: =01_Inputs!C108 | D38: =B38*C38 | E38: =B38*01_Inputs!B108 | F38: =B38*01_Inputs!D108 | G38: =D38/D$41
A39: NonRes | B39: =B23 | C39: =01_Inputs!C109 | D39: =B39*C39 | E39: =B39*01_Inputs!B109 | F39: =B39*01_Inputs!D109 | G39: =D39/D$41
A40: Less: G&A capitalized | B40: =-B28 | C40: =01_Inputs!C110 | D40: =B40*C40 | E40: =B40*01_Inputs!B110 | F40: =B40*01_Inputs!D110 | G40: =D40/D$41
A41: TOTAL Ops EV (segment sum) | D41: =SUM(D35:D40) | E41: =SUM(E35:E40) | F41: =SUM(F35:F40)
A43: + Cash | D43: =01_Inputs!B16
A44: − Gross debt | D44: =-01_Inputs!B17
A45: Equity value (segment multiples) | D45: =D41+D43+D44
A46: $/sh (segment multiples base) | D46: =D45/01_Inputs!B7
A47: $/sh bull / bear | E47: =(E41+01_Inputs!B16-01_Inputs!B17)/01_Inputs!B7 | F47: =(F41+01_Inputs!B16-01_Inputs!B17)/01_Inputs!B7
A49: UNIT ECONOMICS (from Q2 seeds / RP beds)
A50: Owned Secure rev $/RP-bed | B50: =01_Inputs!B96*1000/01_Inputs!B51
...

Sheet 04_IS_Fwd
A1: CONSOLIDATED P&L FORWARD ($M) — formulas from Segments + Inputs
B3: FY26E | C3: FY27E | D3: FY28E | E3: FY29E
A4: Revenue | B4: =03_Segments!B25 | C4: =03_Segments!C25 | D4: =03_Segments!D25 | E4: =03_Segments!E25
A5: YoY growth | C5: =C4/B4-1 | D5: =D4/C4-1 | E5: =E4/D4-1
A6: Adj EBITDA | B6: =03_Segments!B30 | C6: =03_Segments!C30 | D6: =03_Segments!D30 | E6: =03_Segments!E30
A7: EBITDA margin | B7: =B6/B4 | C7: =C6/C4 | D7: =D6/D4 | E7: =E6/E4
A8: D&A | B8: 139 | C8: =B8*1.02 | D8: =C8*1.02 | E8: =D8*0.95
A9: EBIT (EBITDA − D&A) | B9: =B6-B8 | C9: =C6-C8 | D9: =D6-D8 | E9: =E6-E8
A10: Net interest | B10: =01_Inputs!B75 | C10: =B10*0.90 | D10: =C10*0.95 | E10: =D10*1.05
A11: EBT | B11: =B9-B10 | C11: =C9-C10 | D11: =D9-D10 | E11: =E9-E10
A12: ETR | B12: =01_Inputs!B30 | C12: =01_Inputs!B30 | D12: =01_Inputs!B30 | E12: =01_Inputs!B30
A13: Net income (ops, ex RE gains) | B13: =B11*(1-B12) | C13: =C11*(1-C12) | D13: =D11*(1-D12) | E13: =E11*(1-E12)
A14: Diluted shares M | B14: =01_Inputs!B8 | C14: 128 | D14: 125 | E14: 122
A15: EPS (ops) | B15: =B13/B14 | C15: =C13/C14 | D15: =D13/D14 | E15: =E13/E14
A16: P/E at current price | B16: =01_Inputs!B6/B15 | C16: =01_Inputs!B6/C15 | D16: =01_Inputs!B6/D15 | E16: =01_Inputs!B6/E15
A17: Price at target mid-cycle P/E | B17: =B15*01_Inputs!B117 | C17: =C15*01_Inputs!B117 | D17: =D15*01_Inputs!B117 | E17: =E15*01_Inputs!B117
A18: CapEx | B18: =01_Inputs!B76 | C18: 95 | D18: 90 | E18: 85
A19: FCF proxy (EBITDA − cash int − tax on EBT − CapEx) | B19: =B6-B10-B11*B12-B18 | C19: =C6-C10-C11*C12-C18 | D19: =D6-D10-D11*D12-D18 | E19: =E6-E10-E11*E12-E18
A21: Note: RE sale gains are modeled on 06_RE_NAV / 07_SOTP, not in ops NI above.
A23: EDITABLE INTEREST / D&A PATHS (blue)
A24: Interest 2027–29 currently = prior × factor. Overwrite C10:E10 with hard values if modeling a large debt paydown from RE sale.

Sheet 05_BS_Fwd
A1: BALANCE SHEET / CASH BRIDGE ($M)
B3: 6/30/26A | C3: FY26E | D3: FY27E | E3: FY28E | F3: FY29E
A4: Cash | B4: =01_Inputs!B16 | C4: 80 | D4: 200 | E4: 250 | F4: 200
A5: Gross debt | B5: =01_Inputs!B17 | C5: 1480 | D5: 1100 | E5: 1000 | F5: 1050
A6: Net debt | B6: =B5-B4 | C6: =C5-C4 | D6: =D5-D4 | E6: =E5-E4 | F6: =F5-F4
A7: Net leverage (x FY EBITDA) | B7: =B6/01_Inputs!B71 | C7: =C6/'04_IS_Fwd'!B6 | D7: =D6/'04_IS_Fwd'!C6 | E7: =E6/'04_IS_Fwd'!D6 | F7: =F6/'04_IS_Fwd'!E6
A8: Equity book | B8: =01_Inputs!B20 | C8: 1600 | D8: 1900 | E8: 2100 | F8: 2200
A10: Cash in equity bridge check | B10: =01_Inputs!B16
A11: Mkt cap | B11: =01_Inputs!B11
A12: EV = mkt + net debt | B12: =01_Inputs!B23
A13: EV = mkt + gross debt − cash (same) | B13: =B11+B5-B4
A15: Edit blue cash/debt paths for each scenario manually, or link to sale proceeds from 06_RE_NAV.
A17: FCF from IS (FY26E–29E)
A18: FCF proxy | C18: ='04_IS_Fwd'!B19 | D18: ='04_IS_Fwd'!C19 | E18: ='04_IS_Fwd'!D19 | F18: ='04_IS_Fwd'!E19
A19: Memo: starting cash + cumulative FCF − debt pay − buybacks should reconcile to cash path (edit blue cash/debt to match scenario).

Sheet 06_RE_NAV
A1: REAL ESTATE NAV — formula-driven
A3: Bucket | B3: Beds | C3: $/bed | D3: Gross $M | E3: Net $M | F3: Net $/sh
A4: ICE + dual | B4: =01_Inputs!B40 | C4: =01_Inputs!B55 | D4: =B4*C4/1000000 | E4: =D4*01_Inputs!B33 | F4: =E4/01_Inputs!B7
A5: Other owned secure | B5: =01_Inputs!B44 | C5: =01_Inputs!B56 | D5: =B5*C5/1000000 | E5: =D5*01_Inputs!B33 | F5: =E5/01_Inputs!B7
A6: Reentry / other | B6: =01_Inputs!B46 | C6: =01_Inputs!B59 | D6: =B6*C6/1000000 | E6: =D6*01_Inputs!B33 | F6: =E6/01_Inputs!B7
A7: TOTAL RE | B7: =B4+B5+B6 | D7: =D4+D5+D6 | E7: =E4+E5+E6 | F7: =E7/01_Inputs!B7
A9: Several sale only | B9: =01_Inputs!B122 | C9: =01_Inputs!B55 | D9: =B9*C9/1000000 | E9: =D9*01_Inputs!B33 | F9: =E9/01_Inputs!B7
A11: TAX BUILD-UP
A12: Federal statutory | B12: =01_Inputs!B27
A13: State/other add | B13: =01_Inputs!B28
A14: Tax on gain used | B14: =01_Inputs!B32
A15: Txn costs | B15: =01_Inputs!B31
A16: Net take | B16: =01_Inputs!B33
A17: Why not (1−21%)? Gain tax applies to (price − tax basis), not price. Low NBV → effective tax ≈ mid-20%s of gross + txn ≈ ~28% friction (CXW ~27–29%). Edit 01_Inputs!B32.
A19: RESIDUAL EBITDA AFTER SALE
A20: FY26 EBITDA | B20: =01_Inputs!B71
A21: Blend cut $/bed | B21: =01_Inputs!B66
A22: Beds sold (full ICE) | B22: =01_Inputs!B121
A23: EBITDA cut $M | B23: =B22*B21/1000000
A24: Residual EBITDA (ICE sale) | B24: =B20-B23
A25: Other owned RP beds approx | B25: =MAX(01_Inputs!B51-B22,0)
A26: Extra cut if MTM all RE (full gap on other) | B26: =B25*01_Inputs!B64/1000000
A27: Asset-light residual | B27: =B24-B26

Sheet 07_SOTP
A1: SUM OF THE PARTS — pick ONE primary approach (avoid double-count)
A3: APPROACH A — Segment multiples ops + cash − debt (NO separate RE NAV)
A4: Ops EV (from 03_Segments) | B4: =03_Segments!D41
A5: + Cash | B5: =01_Inputs!B16
A6: − Gross debt | B6: =-01_Inputs!B17
A7: Equity $M | B7: =B4+B5+B6
A8: $/sh | B8: =B7/01_Inputs!B7
A10: APPROACH B — Sell ICE RE + residual EBITDA multiple (keeps other owned in residual)
A11: ICE RE net proceeds | B11: =06_RE_NAV!E4
A12: − Net debt | B12: =-01_Inputs!B18
A13: + Cash already in net debt | C13: (net debt = gross−cash; don't add cash again)
A14: Cash after debt repay | B14: =B11+B12
A15: Residual EBITDA | B15: =06_RE_NAV!B24
A16: × multiple | B16: =01_Inputs!B114
A17: Ops EV | B17: =B15*B16
A18: Equity $M | B18: =B14+B17
A19: $/sh | B19: =B18/01_Inputs!B7
A21: APPROACH C — MTM all RE + asset-light residual (full re-rate)
A22: Total RE net | B22: =06_RE_NAV!E7
A23: − Net debt | B23: =-01_Inputs!B18
A24: Cash after debt | B24: =B22+B23
A25: AL residual EBITDA | B25: =06_RE_NAV!B27
A26: × multiple | B26: =01_Inputs!B115
A27: Ops EV | B27: =B25*B26
A28: Equity $M | B28: =B24+B27
A29: $/sh | B29: =B28/01_Inputs!B7
A31: APPROACH D — Several sale only + consolidated EBITDA multiple on unsold
A32: Several net proceeds | B32: =06_RE_NAV!E9
A33: EBITDA after several cut | B33: =01_Inputs!B71-01_Inputs!B122*01_Inputs!B66/1000000
A34: Debt after applying several proceeds (max zero) | B34: =MAX(01_Inputs!B18-B32,0)
A35: Surplus cash if proceeds > net debt | B35: =MAX(B32-01_Inputs!B18,0)
A36: Ops EV | B36: =B33*01_Inputs!B114
A37: Equity $M | B37: =B36-B34+B35
A38: $/sh | B38: =B37/01_Inputs!B7
A40: CURRENT MARKET
A41: Price | B41: =01_Inputs!B6
A42: Mkt cap | B42: =01_Inputs!B11
A43: Upside/(downside) vs Approach B | B43: =B19/B41-1
A44: Upside/(downside) vs Approach A | B44: =B8/B41-1
A46: CASH EXPLICITLY IN BRIDGE: Approaches A uses +Cash −GrossDebt. B/C use NetDebt (=Gross−Cash) so cash is included once. Do not add cash on top of net debt.

Sheet 08_CXW_Comps
A1: CORECIVIC COMPS
A3: Trading | B3: GEO | C3: CXW | D3: Formula/notes
A4: Price | B4: =01_Inputs!B6 | C4: =01_Inputs!B9
A5: Mkt cap | B5: =01_Inputs!B11 | C5: =01_Inputs!B12
A6: Net debt / (cash) | B6: =01_Inputs!B18 | C6: -260
A7: EV | B7: =B5+B6 | C7: =C5+C6
A8: FY26E EBITDA | B8: =01_Inputs!B71 | C8: 443
A9: EV/EBITDA | B9: =B7/B8 | C9: =C7/C8
A10: P/E on GEO guide | B10: =01_Inputs!B78 | C10: 14.9
A12: Transaction comps (editable)
A13: Facility | B13: Beds | C13: Price $M | D13: $/bed
A14: Otay Mesa | B14: 1994 | C14: 739.2 | D14: =C14*1000000/B14
A15: California City | B15: 2560 | C15: 732.6 | D15: =C15*1000000/B15
A16: Prairie | B16: 1600 | C16: 495.6 | D16: =C16*1000000/B16
A17: Midwest | B17: 1033 | C17: 238.4 | D17: =C17*1000000/B17
A18: TOTAL / AVG | B18: =SUM(B14:B17) | C18: =SUM(C14:C17) | D18: =C18*1000000/B18
A19: Link: set 01_Inputs ICE $/bed = this avg? | B19: =D18
D20: Copy into 01_Inputs!B55 if you want live link — or keep B55 as override

Sheet 09_Scenarios
A1: SCENARIO DASHBOARD — outputs are formulas; probabilities are inputs
A3: Scenario | B3: Prob | C3: Value $/sh | D3: Source | E3: Notes
A4: A Segment multiples (no RE sale) | B4: 0.2 | C4: =07_SOTP!B8 | D4: 07_SOTP Approach A
A5: B Full ICE sale SOTP | B5: 0.15 | C5: =07_SOTP!B19 | D5: 07_SOTP Approach B
A6: C Full RE NAV re-rate | B6: 0.1 | C6: =07_SOTP!B29 | D6: 07_SOTP Approach C
A7: D Several sales only | B7: 0.35 | C7: =07_SOTP!B38 | D7: 07_SOTP Approach D
A8: E Bear political (EBITDA×bear mult − net debt)/sh | B8: 0.2 | C8: =(04_IS_Fwd!E6*01_Inputs!B116-01_Inputs!B18)/01_Inputs!B7 | D8: 2029E EBITDA × bear multiple
A9: Prob check (should be 100%) | B9: =SUM(B4:B8)
A10: Probability-weighted value | C10: =B4*C4+B5*C5+B6*C6+B7*C7+B8*C8
A11: vs market | C11: =C10/01_Inputs!B6-1
A13: PE COMPRESSION (no sale)
A14: EPS FY26 | B14: =04_IS_Fwd!B15
A15: Price @ 12x | B15: =B14*12
A16: Price @ 15x | B16: =B14*01_Inputs!B117
A17: Price @ 18x | B17: =B14*01_Inputs!B118
A18: Price @ spot P/E | B18: =B14*01_Inputs!B78
